<?xml version="1.0"?>
<robot name="myrobot">
    <link name="bigger">
        <visual>
            <geometry>
                <cylinder radius="0.25" length="0.6"/>
            </geometry>
        </visual>
        <collision>
            <geometry>
                <cylinder radius="0.25" length="0.6"/>
            </geometry>
        </collision> 
        <inertial>
            <mass value="0.25"/>
             <inertia ixx="0.0003" ixy="0.0002" ixz="0.0" iyy="0.0" iyz="0.0" izz="0.0"/>
        </inertial>
    </link>
    <link name="tiny">
        <visual>
            <geometry>
                <cylinder radius="0.15" length="1.0"/>
            </geometry>
        </visual>
        <collision>
            <geometry>
                <cylinder radius="0.15" length="1.0"/>
            </geometry>
        </collision> 
        <inertial>
            <mass value="0.25"/>
             <inertia ixx="0.0003" ixy="0.0002" ixz="0.0" iyy="0.0" iyz="0.0" izz="0.0"/>
        </inertial>
    </link>
    <joint name="big_to_tiny" type="revolute">
        <origin xyz="0.0 0.25 0.0" rpy="0.0 0.0 0.0"/>
        <parent link="bigger"/>
        <child link="tiny"/>
        <axis xyz="1 0 0"/>
        <limit lower="10.0 " upper="0.0" effort="10.0" velocity="10.0"/>
    </joint>        
</robot>